<mujoco model="ym1">
    <compiler angle="radian" meshdir="meshes" />
    <default>
        <motor ctrlrange="-1 1" ctrllimited="true"/>
        <joint actuatorfrclimited="true" type="hinge"/>
    </default>
    <asset>
        <mesh name="base_link" file="base_link.STL" />
        <mesh name="left_leg_pitch_link" file="left_leg_pitch_link.STL" />
        <mesh name="left_leg_roll_link" file="left_leg_roll_link.STL" />
        <mesh name="left_leg_yaw_link" file="left_leg_yaw_link.STL" />
        <mesh name="left_knee_pitch_link" file="left_knee_pitch_link.STL" />
        <mesh name="left_ankle_pitch_link" file="left_ankle_pitch_link.STL" />
        <mesh name="left_ankle_roll_link" file="left_ankle_roll_link.STL" />
        <mesh name="right_leg_pitch_link" file="right_leg_pitch_link.STL" />
        <mesh name="right_leg_roll_link" file="right_leg_roll_link.STL" />
        <mesh name="right_leg_yaw_link" file="right_leg_yaw_link.STL" />
        <mesh name="right_knee_pitch_link" file="right_knee_pitch_link.STL" />
        <mesh name="right_ankle_pitch_link" file="right_ankle_pitch_link.STL" />
        <mesh name="right_ankle_roll_link" file="right_ankle_roll_link.STL" />
        <mesh name="waist_yaw_link" file="waist_yaw_link.STL" />
        <mesh name="left_shoulder_pitch_link" file="left_shoulder_pitch_link.STL" />
        <mesh name="left_shoulder_roll_link" file="left_shoulder_roll_link.STL" />
        <mesh name="left_shoulder_yaw_link" file="left_shoulder_yaw_link.STL" />
        <mesh name="left_elbow_pitch_link" file="left_elbow_pitch_link.STL" />
        <mesh name="left_elbow_roll_link" file="left_elbow_roll_link.STL" />
        <mesh name="left_wrist_pitch_link" file="left_wrist_pitch_link.STL" />
        <mesh name="left_wrist_yaw_link" file="left_wrist_yaw_link.STL" />
        <mesh name="right_shoulder_pitch_link" file="right_shoulder_pitch_link.STL" />
        <mesh name="right_shoulder_roll_link" file="right_shoulder_roll_link.STL" />
        <mesh name="right_shoulder_yaw_link" file="right_shoulder_yaw_link.STL" />
        <mesh name="right_elbow_pitch_link" file="right_elbow_pitch_link.STL" />
        <mesh name="right_elbow_roll_link" file="right_elbow_roll_link.STL" />
        <mesh name="right_wrist_pitch_link" file="right_wrist_pitch_link.STL" />
        <mesh name="right_wrist_yaw_link" file="right_wrist_yaw_link.STL" />
        <mesh name="neck_yaw_link" file="neck_yaw_link.STL" />
        <mesh name="neck_pitch_link" file="neck_pitch_link.STL" />
    </asset>
    <worldbody>
        <body name="base_link" pos="0 0 0.753">
            <site name="imu_in_pelvis" size="0.01" pos="0.04525 0 -0.08339"/>
            <freejoint name="base_link"/>
            <inertial pos="4.6721e-06 -2.3326e-07 -0.030542" quat="1 0 0 0" mass="3.13" diaginertia="0.010908 0.010341 0.006614"/>
            <geom type="mesh" contype="0" conaffinity="0" group="1" rgba="0.77255 0.75294 0.73333 1" mesh="base_link" />
            <body name="left_leg_pitch_link" pos="0 0.057 -0.06025">
                <inertial pos="-0.0022424 0.052941 0.0018571" quat="0.752509 0.658284 0.015395 0.0124575" mass="1.06" diaginertia="0.00194632 0.00155248 0.0012298" />
                <joint name="left_leg_pitch_joint" pos="0 0 0" axis="0 1 0" limited="true" range="-2.792 2.792" />
                <geom type="mesh" contype="0" conaffinity="0" group="1" rgba="0.69804 0.69804 0.69804 1" mesh="left_leg_pitch_link" />
                <body name="left_leg_roll_link" pos="0 0.06 0">
                    <inertial pos="0.002441 3.17e-05 -0.092183" quat="0.704331 0.0779721 0.0782927 0.701219" mass="0.8" diaginertia="0.001629 0.00157239 0.000909228" />
                    <joint name="left_leg_roll_joint" pos="0 0 0" axis="1 0 0" limited="true" range="-0.087 3.037" />
                    <geom type="mesh" contype="0" conaffinity="0" group="1" rgba="0.69804 0.69804 0.69804 1" mesh="left_leg_roll_link" />
                    <geom type="mesh" rgba="0.69804 0.69804 0.69804 1" mesh="left_leg_roll_link" />
                    <body name="left_leg_yaw_link" pos="0 0 -0.127">
                        <inertial pos="0.0010862 -0.00087371 -0.15709" quat="0.706298 0.0243242 0.025669 0.70703" mass="2.93" diaginertia="0.00984302 0.008308 0.00364108" />
                        <joint name="left_leg_yaw_joint" pos="0 0 0" axis="0 0 1" limited="true" range="-2.269 2.269" />
                        <geom type="mesh" contype="0" conaffinity="0" group="1" rgba="0.69804 0.69804 0.69804 1" mesh="left_leg_yaw_link" />
                        <geom type="mesh" rgba="0.69804 0.69804 0.69804 1" mesh="left_leg_yaw_link" />
                        <body name="left_knee_pitch_link" pos="0 0 -0.173">
                            <inertial pos="-0.0032204 0.0014598 -0.13449" quat="0.711453 -0.012985 0.0334371 0.701817" mass="2.19" diaginertia="0.0180089 0.0168248 0.00290915" />
                            <joint name="left_knee_pitch_joint" pos="0 0 0" axis="0 1 0" limited="true" range="-0.052 2.618" />
                            <geom type="mesh" contype="0" conaffinity="0" group="1" rgba="0.69804 0.69804 0.69804 1" mesh="left_knee_pitch_link" />
                            <geom size="0.065 0.035 0.07" pos="0 0 -0.13" type="box" rgba="0.69804 0.69804 0.69804 1" />
                            <body name="left_ankle_pitch_link" pos="0 0 -0.3">
                                <inertial pos="0 0 0" mass="0.16" diaginertia="0.03 0.03 0.03" />
                                <joint name="left_ankle_pitch_joint" pos="0 0 0" axis="0 1 0" limited="true" range="-0.87267 0.5236" />
                                <geom type="mesh" contype="0" conaffinity="0" group="1" rgba="0.69804 0.69804 0.69804 1" mesh="left_ankle_pitch_link" />
                                <body name="left_ankle_roll_link" pos="0 0 0">
                                    <inertial pos="0.018367 0 -0.022988" quat="0.00125164 0.923879 -8.89481e-05 0.382683" mass="1.01" diaginertia="0.0100891 0.01 0.0099109" />
                                    <joint name="left_ankle_roll_joint" pos="0 0 0" axis="1 0 0" limited="true" range="-0.349 0.349" />
                                    <geom type="mesh" contype="0" conaffinity="0" group="1" rgba="0.69804 0.69804 0.69804 1" mesh="left_ankle_roll_link" />
                                    <geom type="mesh" rgba="0.69804 0.69804 0.69804 1" mesh="left_ankle_roll_link" />
                                </body>
                            </body>
                        </body>
                    </body>
                </body>
            </body>
            <body name="right_leg_pitch_link" pos="0 -0.057 -0.06025">
                <inertial pos="-0.0022424 -0.052767 0.0018571" quat="0.658272 0.752573 -0.0106005 -0.0141088" mass="1.06" diaginertia="0.00194349 0.00154983 0.00123008" />
                <joint name="right_leg_pitch_joint" pos="0 0 0" axis="0 1 0" limited="true" range="-2.792 2.792" />
                <geom type="mesh" contype="0" conaffinity="0" group="1" rgba="0.69804 0.69804 0.69804 1" mesh="right_leg_pitch_link" />
                <body name="right_leg_roll_link" pos="0 -0.06 0">
                    <inertial pos="0.002441 3.17e-05 -0.092183" quat="0.704331 0.0779721 0.0782927 0.701219" mass="0.8" diaginertia="0.001629 0.00157239 0.000909228" />
                    <joint name="right_leg_roll_joint" pos="0 0 0" axis="1 0 0" limited="true" range="-3.037 0.087" />
                    <geom type="mesh" contype="0" conaffinity="0" group="1" rgba="0.69804 0.69804 0.69804 1" mesh="right_leg_roll_link" />
                    <geom type="mesh" rgba="0.69804 0.69804 0.69804 1" mesh="right_leg_roll_link" />
                    <body name="right_leg_yaw_link" pos="0 0 -0.127">
                        <inertial pos="0.0010862 0.00087371 -0.15709" quat="0.70703 0.025669 0.0243242 0.706298" mass="2.93" diaginertia="0.00984302 0.008308 0.00364108" />
                        <joint name="right_leg_yaw_joint" pos="0 0 0" axis="0 0 1" limited="true" range="-2.269 2.269" />
                        <geom type="mesh" contype="0" conaffinity="0" group="1" rgba="0.69804 0.69804 0.69804 1" mesh="right_leg_yaw_link" />
                        <geom type="mesh" rgba="0.69804 0.69804 0.69804 1" mesh="right_leg_yaw_link" />
                        <body name="right_knee_pitch_link" pos="0 0 -0.173">
                            <inertial pos="-0.0032204 -0.0014598 -0.13449" quat="0.701914 0.0334506 -0.0130098 0.711357" mass="2.19" diaginertia="0.018008 0.0168238 0.00290876" />
                            <joint name="right_knee_pitch_joint" pos="0 0 0" axis="0 1 0" limited="true" range="-0.052 2.618" />
                            <geom type="mesh" contype="0" conaffinity="0" group="1" rgba="0.89804 0.91373 0.92549 1" mesh="right_knee_pitch_link" />
                            <geom size="0.065 0.035 0.07" pos="0 0 -0.13" type="box" rgba="0.89804 0.91373 0.92549 1" />
                            <body name="right_ankle_pitch_link" pos="0 0 -0.3">
                                <inertial pos="0 0 0" mass="0.16" diaginertia="0.03 0.03 0.03" />
                                <joint name="right_ankle_pitch_joint" pos="0 0 0" axis="0 1 0" limited="true" range="-0.87267 0.5236" />
                                <geom type="mesh" contype="0" conaffinity="0" group="1" rgba="0.69804 0.69804 0.69804 1" mesh="right_ankle_pitch_link" />
                                <body name="right_ankle_roll_link" pos="0 0 0">
                                    <inertial pos="0.018366 0 -0.023002" quat="0.00125164 0.923879 -8.89481e-05 0.382683" mass="1.01" diaginertia="0.0100891 0.01 0.0099109" />
                                    <joint name="right_ankle_roll_joint" pos="0 0 0" axis="1 0 0" limited="true" range="-0.349 0.349" />
                                    <geom type="mesh" contype="0" conaffinity="0" group="1" rgba="0.69804 0.69804 0.69804 1" mesh="right_ankle_roll_link" />
                                    <geom type="mesh" rgba="0.69804 0.69804 0.69804 1" mesh="right_ankle_roll_link" />
                                </body>
                            </body>
                        </body>
                    </body>
                </body>
            </body>
            <body name="torso_link" pos="0 0 0.05725">
                <inertial pos="-2.98e-06 8.41e-06 0.25361" quat="1 2.56962e-05 -0.000338274 -1.82067e-05" mass="2.6616" diaginertia="0.035915 0.030172 0.00778699" />
                <joint name="waist_yaw_joint" pos="0 0 0" axis="0 0 1" limited="true" range="-0.96 0.96" />
                <geom type="mesh" contype="0" conaffinity="0" group="1" rgba="0.69804 0.69804 0.69804 1" mesh="waist_yaw_link" />
                <geom size="0.05 0.075 0.1" pos="0 0 0.15" type="box" rgba="0.69804 0.69804 0.69804 1" />
                <body name="left_shoulder_pitch_link" pos="0 0.079102 0.32072" quat="0.991445 0.130526 0 0">
                    <inertial pos="0.0074125 0.055258 2.03e-05" quat="0.567601 0.423327 -0.566828 0.421104" mass="0.51" diaginertia="0.000484291 0.00041402 0.000331909" />
                    <joint name="left_shoulder_pitch_joint" pos="0 0 0" axis="0 1 0" limited="true" range="-1.57 1.57" />
                    <geom type="mesh" contype="0" conaffinity="0" group="1" rgba="0.69804 0.69804 0.69804 1" mesh="left_shoulder_pitch_link" />
                    <body name="left_shoulder_roll_link" pos="0 0.064 0" quat="0.991445 -0.130526 0 0">
                        <inertial pos="0.0084543 -7.54e-06 -0.073356" quat="0.67525 0.158196 0.151853 0.704239" mass="0.64" diaginertia="0.000713745 0.000710817 0.000328708" />
                        <joint name="left_shoulder_roll_joint" pos="0 0 0" axis="1 0 0" limited="true" range="-0.1 3.14" />
                        <geom type="mesh" contype="0" conaffinity="0" group="1" rgba="0.69804 0.69804 0.69804 1" mesh="left_shoulder_roll_link" />
                        <body name="left_shoulder_yaw_link" pos="0.00013761 0 -0.103">
                            <inertial pos="-0.00056928 0.0074854 -0.089061" quat="0.994426 0.10318 -0.0216525 0.00162288" mass="0.49" diaginertia="0.000540209 0.000472897 0.000318233" />
                            <joint name="left_shoulder_yaw_joint" pos="0 0 0" axis="0 0 1" limited="true" range="-1.57 1.57" />
                            <geom type="mesh" contype="0" conaffinity="0" group="1" rgba="0.69804 0.69804 0.69804 1" mesh="left_shoulder_yaw_link" />
                            <body name="left_elbow_pitch_link" pos="-0.00013761 0 -0.097">
                                <inertial pos="0.073356 0.0084377 7.54e-06" quat="0.170176 0.692955 -0.140338 0.68641" mass="0.64" diaginertia="0.000713925 0.000711082 0.000328622" />
                                <joint name="left_elbow_pitch_joint" pos="0 0 0" axis="0 1 0" limited="true" range="-1.57 1.57" />
                                <geom type="mesh" contype="0" conaffinity="0" group="1" rgba="0.69804 0.69804 0.69804 1" mesh="left_elbow_pitch_link" />
                                <geom type="mesh" rgba="0.69804 0.69804 0.69804 1" mesh="left_elbow_pitch_link" />
                                <body name="left_elbow_roll_link" pos="0.103 -0.00013761 0">
                                    <inertial pos="0.041845 0.0052481 0.00015646" quat="-0.056949 0.706104 -0.0199542 0.705532" mass="0.45701" diaginertia="0.000202926 0.000189706 0.000156278" />
                                    <joint name="left_elbow_roll_joint" pos="0 0 0" axis="1 0 0" limited="true" range="-1.57 1.57" />
                                    <geom type="mesh" contype="0" conaffinity="0" group="1" rgba="0.69804 0.69804 0.69804 1" mesh="left_elbow_roll_link" />
                                    <body name="left_wrist_pitch_link" pos="0.097 0.00013761 0">
                                        <inertial pos="-3.08e-06 7.559e-05 0.0057017" quat="0.492046 0.509081 -0.507014 0.491593" mass="0.43" diaginertia="0.000148195 0.00014047 0.000133705" />
                                        <joint name="left_wrist_pitch_joint" pos="0 0 0" axis="0 1 0" limited="true" range="-1.57 1.57" />
                                        <geom type="mesh" contype="0" conaffinity="0" group="1" rgba="0.69804 0.69804 0.69804 1" mesh="left_wrist_pitch_link" />
                                        <body name="left_wrist_yaw_link" pos="0 0 0">
                                            <inertial pos="0.10225 -0.0074062 0.0096664" quat="0.299442 0.647961 0.3816 0.587251" mass="0.55" diaginertia="0.00188092 0.00150343 0.000577846" />
                                            <joint name="left_wrist_yaw_joint" pos="0 0 0" axis="0 0 1" limited="true" range="-1.57 1.57" />
                                            <geom type="mesh" contype="0" conaffinity="0" group="1" rgba="1 1 1 1" mesh="left_wrist_yaw_link" />
                                            <geom type="mesh" rgba="1 1 1 1" mesh="left_wrist_yaw_link" />
                                        </body>
                                    </body>
                                </body>
                            </body>
                        </body>
                    </body>
                </body>
                <body name="right_shoulder_pitch_link" pos="0 -0.079102 0.32072" quat="0.991445 -0.130526 0 0">
                    <inertial pos="0.0074125 -0.055258 1.602e-05" quat="0.421005 0.56663 -0.423426 0.5678" mass="0.51" diaginertia="0.000484291 0.000414019 0.000331909" />
                    <joint name="right_shoulder_pitch_joint" pos="0 0 0" axis="0 1 0" limited="true" range="-1.57 1.57" />
                    <geom type="mesh" contype="0" conaffinity="0" group="1" rgba="0.69804 0.69804 0.69804 1" mesh="right_shoulder_pitch_link" />
                    <body name="right_shoulder_roll_link" pos="0 -0.064 0" quat="0.991445 0.130526 0 0">
                        <inertial pos="0.0084253 7.69e-06 -0.073356" quat="0.682119 0.156742 0.153267 0.697607" mass="0.64" diaginertia="0.000714062 0.00071067 0.000329178" />
                        <joint name="right_shoulder_roll_joint" pos="0 0 0" axis="1 0 0" limited="true" range="-3.14 0.1" />
                        <geom type="mesh" contype="0" conaffinity="0" group="1" rgba="0.69804 0.69804 0.69804 1" mesh="right_shoulder_roll_link" />
                        <body name="right_shoulder_yaw_link" pos="0.00013761 0 -0.103">
                            <inertial pos="-0.00056932 -0.0074855 -0.089041" quat="0.994405 -0.103265 -0.022184 -0.00191662" mass="0.49" diaginertia="0.000540069 0.000472743 0.000318208" />
                            <joint name="right_shoulder_yaw_joint" pos="0 0 0" axis="0 0 1" limited="true" range="-1.57 1.57" />
                            <geom type="mesh" contype="0" conaffinity="0" group="1" rgba="0.69804 0.69804 0.69804 1" mesh="right_shoulder_yaw_link" />
                            <body name="right_elbow_pitch_link" pos="-0.00013761 0 -0.097">
                                <inertial pos="0.073356 -0.0084377 -7.54e-06" quat="-0.140338 0.68641 0.170176 0.692955" mass="0.64" diaginertia="0.000713925 0.000711082 0.000328622" />
                                <joint name="right_elbow_pitch_joint" pos="0 0 0" axis="0 1 0" limited="true" range="-1.57 1.57" />
                                <geom type="mesh" contype="0" conaffinity="0" group="1" rgba="0.77255 0.75294 0.73333 1" mesh="right_elbow_pitch_link" />
                                <geom type="mesh" rgba="0.77255 0.75294 0.73333 1" mesh="right_elbow_pitch_link" />
                                <body name="right_elbow_roll_link" pos="0.103 0.00013761 0">
                                    <inertial pos="0.041845 -0.0052481 0.00015645" quat="0.056949 0.706104 0.0199542 0.705532" mass="0.45701" diaginertia="0.000202926 0.000189706 0.000156278" />
                                    <joint name="right_elbow_roll_joint" pos="0 0 0" axis="1 0 0" limited="true" range="-1.57 1.57" />
                                    <geom type="mesh" contype="0" conaffinity="0" group="1" rgba="0.69804 0.69804 0.69804 1" mesh="right_elbow_roll_link" />
                                    <body name="right_wrist_pitch_link" pos="0.097 -0.00013761 0">
                                        <inertial pos="-3.09e-06 -7.559e-05 0.0057017" quat="0.509081 0.492046 -0.491593 0.507014" mass="0.43" diaginertia="0.000148195 0.00014047 0.000133705" />
                                        <joint name="right_wrist_pitch_joint" pos="0 0 0" axis="0 1 0" limited="true" range="-1.57 1.57" />
                                        <geom type="mesh" contype="0" conaffinity="0" group="1" rgba="0.89804 0.91373 0.92549 1" mesh="right_wrist_pitch_link" />
                                        <body name="right_wrist_yaw_link" pos="0 0 0">
                                            <inertial pos="0.102253 0.00741158 0.00966516" quat="0.587231 0.381635 0.647944 0.299471" mass="0.55" diaginertia="0.00188099 0.00150342 0.000577823" />
                                            <joint name="right_wrist_yaw_joint" pos="0 0 0" axis="0 0 1" limited="true" range="-1.57 1.57" />
                                            <geom type="mesh" contype="0" conaffinity="0" group="1" rgba="0.89804 0.91373 0.92549 1" mesh="right_wrist_yaw_link" />
                                            <geom type="mesh" rgba="0.89804 0.91373 0.92549 1" mesh="right_wrist_yaw_link" />
                                        </body>
                                    </body>
                                </body>
                            </body>
                        </body>
                    </body>
                </body>
                <body name="neck_yaw_link" pos="0 0 0.30273">
                    <inertial pos="2e-05 -0.0078274 0.10031" quat="0.994343 0.106204 -0.000111376 -0.00132544" mass="0.45" diaginertia="0.000458101 0.000386499 0.000296401" />
                    <joint name="neck_yaw_joint" pos="0 0 0" axis="0 0 1" limited="true" range="-0.2 0.2" />
                    <geom type="mesh" contype="0" conaffinity="0" group="1" rgba="0.77255 0.75294 0.73333 1" mesh="neck_yaw_link" />
                    <body name="neck_pitch_link" pos="-1.26e-05 -0.031 0.10591">
                        <inertial pos="0.05962 0.029873 0.10199" quat="0.440196 0.39057 -0.62693 0.510531" mass="1.21" diaginertia="0.00222397 0.00162565 0.000978441" />
                        <joint name="neck_pitch_joint" pos="0 0 0" axis="0 1 0" limited="true" range="-0.2 0.2" />
                        <geom type="mesh" contype="0" conaffinity="0" group="1" rgba="0.69804 0.69804 0.69804 1" mesh="neck_pitch_link" />
                    </body>
                </body>
            </body>
        </body>
    </worldbody>

    <actuator>
        <motor name="left_leg_pitch_joint" joint="left_leg_pitch_joint"/>
        <motor name="left_leg_roll_joint" joint="left_leg_roll_joint"/>
        <motor name="left_leg_yaw_joint" joint="left_leg_yaw_joint"/>
        <motor name="left_knee_pitch_joint" joint="left_knee_pitch_joint"/>
        <motor name="left_ankle_pitch_joint" joint="left_ankle_pitch_joint"/>
        <motor name="left_ankle_roll_joint" joint="left_ankle_roll_joint"/>
        <motor name="right_leg_pitch_joint" joint="right_leg_pitch_joint"/>
        <motor name="right_leg_roll_joint" joint="right_leg_roll_joint"/>
        <motor name="right_leg_yaw_joint" joint="right_leg_yaw_joint"/>
        <motor name="right_knee_pitch_joint" joint="right_knee_pitch_joint"/>
        <motor name="right_ankle_pitch_joint" joint="right_ankle_pitch_joint"/>
        <motor name="right_ankle_roll_joint" joint="right_ankle_roll_joint"/>
        <motor name="waist_yaw_joint" joint="waist_yaw_joint"/>
        <!-- <motor name="waist_roll_joint" joint="waist_roll_joint"/> -->
        <!-- <motor name="waist_pitch_joint" joint="waist_pitch_joint"/> -->
        <motor name="left_shoulder_pitch_joint" joint="left_shoulder_pitch_joint"/>
        <motor name="left_shoulder_roll_joint" joint="left_shoulder_roll_joint"/>
        <motor name="left_shoulder_yaw_joint" joint="left_shoulder_yaw_joint"/>
        <motor name="left_elbow_pitch_joint" joint="left_elbow_pitch_joint"/>
        <motor name="left_elbow_roll_joint" joint="left_elbow_roll_joint"/>
        <!-- <motor name="left_wrist_roll_joint" joint="left_wrist_roll_joint"/> -->
        <motor name="left_wrist_pitch_joint" joint="left_wrist_pitch_joint"/>
        <motor name="left_wrist_yaw_joint" joint="left_wrist_yaw_joint"/>
        <motor name="right_shoulder_pitch_joint" joint="right_shoulder_pitch_joint"/>
        <motor name="right_shoulder_roll_joint" joint="right_shoulder_roll_joint"/>
        <motor name="right_shoulder_yaw_joint" joint="right_shoulder_yaw_joint"/>
        <motor name="right_elbow_pitch_joint" joint="right_elbow_pitch_joint"/>
        <motor name="right_elbow_roll_joint" joint="right_elbow_roll_joint"/>
        <!-- <motor name="right_wrist_roll_joint" joint="right_wrist_roll_joint"/> -->
        <motor name="right_wrist_pitch_joint" joint="right_wrist_pitch_joint"/>
        <motor name="right_wrist_yaw_joint" joint="right_wrist_yaw_joint"/>
    </actuator>

    <sensor>
        <framequat name='orientation' objtype='site' noise='0.001' objname='imu_in_pelvis'/>
        <framepos name='position' objtype='site' noise='0.001' objname='imu_in_pelvis'/>
        <gyro name='angular-velocity' cutoff='34.9' noise='0.005' site='imu_in_pelvis'/>
    </sensor>


    <!-- setup scene -->
    <statistic center="1.0 0.7 1.0" extent="0.8"/>
    <visual>
        <headlight diffuse="0.6 0.6 0.6" ambient="0.1 0.1 0.1" specular="0.9 0.9 0.9"/>
        <rgba haze="0.15 0.25 0.35 1"/>
        <global azimuth="-140" elevation="-20" offwidth="2080" offheight="1170"/>
    </visual>
    <asset>
        <texture type="skybox" builtin="gradient" rgb1="1 1 1" rgb2="1 1 1" width="800" height="800"/>
        <texture type="2d" name="groundplane" builtin="checker" mark="edge" rgb1="1 1 1" rgb2="1 1 1" markrgb="0 0 0"
        width="300" height="300"/>
        <material name="groundplane" texture="groundplane" texuniform="true" texrepeat="5 5" reflectance="0"/>
        <texture type="skybox" builtin="gradient" rgb1=".4 .5 .6" rgb2="0 0 0" width="100" height="100"/>
        <texture builtin="flat" height="1278" mark="cross" markrgb="1 1 1" name="texgeom" random="0.01" rgb1="0.8 0.6 0.4" rgb2="0.8 0.6 0.4" type="cube" width="127"/>
        <texture name="texplane" builtin="checker" height="512" width="512" rgb1=".2 .3 .4" rgb2=".1 .15 .2" type="2d" />
        <material name="MatPlane" reflectance="0.5" shininess="0.01" specular="0.1" texrepeat="1 1" texture="texplane" texuniform="true" />
        <material name="geom" texture="texgeom" texuniform="true"/>
    </asset>
     <worldbody>
        <geom name="floor" size="0 0 0.01" type="plane" material="groundplane" contype="1" conaffinity="0" priority="1"
        friction="0.6" condim="3"/>

            <light diffuse=".5 .5 .5" pos="-3 -3 5" dir="3 3 -5" castshadow="true"/>

    </worldbody>
</mujoco>
