<?xml version="1.0" encoding="utf-8"?>
<!-- This URDF was automatically created by SolidWorks to URDF Exporter! Originally created by Stephen Brawner (brawner@gmail.com) 
     Commit Version: 1.6.0-4-g7f85cfe  Build Version: 1.6.7995.38578
     For more information, please see http://wiki.ros.org/sw_urdf_exporter -->
<robot
  name="ym1">
    <mujoco>
        <compiler meshdir="meshes" balanceinertia="true" discardvisual="false" />
    </mujoco> 
  <link
    name="pelvis">
    <inertial>
      <origin
        xyz="4.6721E-06 -2.3326E-07 -0.030542"
        rpy="0 0 0" />
      <mass
        value="3.13" />
      <inertia
        ixx="0.010908"
        ixy="-8E-08"
        ixz="3.28E-06"
        iyy="0.010341"
        iyz="1.4E-07"
        izz="0.006614" />
    </inertial>
    <visual>
      <origin
        xyz="0 0 0"
        rpy="0 0 0" />
      <geometry>
        <mesh
          filename="meshes/base_link.STL" />
      </geometry>
      <material
        name="">
        <color
          rgba="0.77255 0.75294 0.73333 1" />
      </material>
    </visual>
    <!-- <collision>
      <origin
        xyz="0 0 0"
        rpy="0 0 0" />
      <geometry>
        <mesh
          filename="meshes/base_link.STL" />
      </geometry>
    </collision> -->
  </link>
  <link
    name="left_leg_pitch_link">
    <inertial>
      <origin
        xyz="-0.0022424 0.052941 0.0018571"
        rpy="0 0 0" />
      <mass
        value="1.06" />
      <inertia
        ixx="0.0019452"
        ixy="2.8E-05"
        ixz="-4.36E-06"
        iyy="0.0012366"
        iyz="4.235E-05"
        izz="0.0015468" />
    </inertial>
    <visual>
      <origin
        xyz="0 0 0"
        rpy="0 0 0" />
      <geometry>
        <mesh
          filename="meshes/left_leg_pitch_link.STL" />
      </geometry>
      <material
        name="">
        <color
          rgba="0.69804 0.69804 0.69804 1" />
      </material>
    </visual>
    <!-- <collision>
      <origin
        xyz="0 0 0"
        rpy="0 0 0" />
      <geometry>
        <mesh
          filename="meshes/left_leg_pitch_link.STL" />
      </geometry>
    </collision> -->
  </link>
  <joint
    name="left_leg_pitch_joint"
    type="revolute">
    <origin
      xyz="0 0.057 -0.06025"
      rpy="0 0 0" />
    <parent
      link="pelvis" />
    <child
      link="left_leg_pitch_link" />
    <axis
      xyz="0 1 0" />
    <limit
      lower="-2.792"
      upper="2.792"
      effort="90"
      velocity="9" />
  </joint>
  <link
    name="left_leg_roll_link">
    <inertial>
      <origin
        xyz="0.002441 3.17E-05 -0.092183"
        rpy="0 0 0" />
      <mass
        value="0.8" />
      <inertia
        ixx="0.0015404"
        ixy="2.5E-07"
        ixz="-0.0001421"
        iyy="0.001629"
        iyz="-3E-08"
        izz="0.00094122" />
    </inertial>
    <visual>
      <origin
        xyz="0 0 0"
        rpy="0 0 0" />
      <geometry>
        <mesh
          filename="meshes/left_leg_roll_link.STL" />
      </geometry>
      <material
        name="">
        <color
          rgba="0.69804 0.69804 0.69804 1" />
      </material>
    </visual>
    <collision>
      <origin
        xyz="0 0 0"
        rpy="0 0 0" />
      <geometry>
        <mesh
          filename="meshes/left_leg_roll_link.STL" />
      </geometry>
    </collision>
  </link>
  <joint
    name="left_leg_roll_joint"
    type="revolute">
    <origin
      xyz="0 0.06 0"
      rpy="0 0 0" />
    <parent
      link="left_leg_pitch_link" />
    <child
      link="left_leg_roll_link" />
    <axis
      xyz="1 0 0" />
    <limit
      lower="-0.087"
      upper="3.037"
      effort="90"
      velocity="9" />
  </joint>
  <link
    name="left_leg_yaw_link">
    <inertial>
      <origin
        xyz="0.0010862 -0.00087371 -0.15709"
        rpy="0 0 0" />
      <mass
        value="2.93" />
      <inertia
        ixx="0.0082847"
        ixy="-2.33E-06"
        ixz="-0.00032892"
        iyy="0.009843"
        iyz="-1.188E-05"
        izz="0.0036644" />
    </inertial>
    <visual>
      <origin
        xyz="0 0 0"
        rpy="0 0 0" />
      <geometry>
        <mesh
          filename="meshes/left_leg_yaw_link.STL" />
      </geometry>
      <material
        name="">
        <color
          rgba="0.69804 0.69804 0.69804 1" />
      </material>
    </visual>
    <collision>
      <origin
        xyz="0 0 0"
        rpy="0 0 0" />
      <geometry>
        <mesh
          filename="meshes/left_leg_yaw_link.STL" />
      </geometry>
    </collision>
    <!-- <collision>
      <origin
        xyz="0 0 0.06"
        rpy="0 0 0" />
      <geometry>
        <box size="0.11 0.11 0.15" />
      </geometry>
    </collision> -->
  </link>
  <joint
    name="left_leg_yaw_joint"
    type="revolute">
    <origin
      xyz="0 0 -0.127"
      rpy="0 0 0" />
    <parent
      link="left_leg_roll_link" />
    <child
      link="left_leg_yaw_link" />
    <axis
      xyz="0 0 1" />
    <limit
      lower="-2.269"
      upper="2.269"
      effort="60"
      velocity="6" />
  </joint>
  <link
    name="left_knee_pitch_link">
    <inertial>
      <origin
        xyz="-0.0032204 0.0014598 -0.13449"
        rpy="0 0 0" />
      <mass
        value="2.19" />
      <inertia
        ixx="0.016813"
        ixy="-1.175E-05"
        ixz="-0.00040839"
        iyy="0.017944"
        iyz="-0.00098562"
        izz="0.0029858" />
    </inertial>
    <visual>
      <origin
        xyz="0 0 0"
        rpy="0 0 0" />
      <geometry>
        <mesh
          filename="meshes/left_knee_pitch_link.STL" />
      </geometry>
      <material
        name="">
        <color
          rgba="0.69804 0.69804 0.69804 1" />
      </material>
    </visual>
    <!-- <collision>
      <origin
        xyz="0 0 0"
        rpy="0 0 0" />
      <geometry>
        <mesh
          filename="meshes/left_knee_pitch_link.STL" />
      </geometry>
    </collision> -->
    <collision>
      <origin
        xyz="0 0 -0.13"
        rpy="0 0 0" />
      <geometry>
        <box size="0.13 0.07 0.14" />
      </geometry>
    </collision>
  </link>
  <joint
    name="left_knee_pitch_joint"
    type="revolute">
    <origin
      xyz="0 0 -0.173"
      rpy="0 0 0" />
    <parent
      link="left_leg_yaw_link" />
    <child
      link="left_knee_pitch_link" />
    <axis
      xyz="0 1 0" />
    <limit
      lower="-0.052"
      upper="2.618"
      effort="150"
      velocity="15" />
  </joint>
  <link
    name="left_ankle_pitch_link">
    <inertial>
      <origin
        xyz="0 0 0"
        rpy="0 0 0" />
      <mass
        value="0.16" />
      <!-- <inertia
        ixx="0.00010835"
        ixy="0"
        ixz="0"
        iyy="5.9E-06"
        iyz="0"
        izz="0.00010835" />
    </inertial> -->
    <inertia ixx="0.03" ixy="0" ixz="0" iyy="0.03" iyz="0" izz="0.03"/> </inertial>
    <visual>
      <origin
        xyz="0 0 0"
        rpy="0 0 0" />
      <geometry>
        <mesh
          filename="meshes/left_ankle_pitch_link.STL" />
      </geometry>
      <material
        name="">
        <color
          rgba="0.69804 0.69804 0.69804 1" />
      </material>
    </visual>
    <!-- <collision>
      <origin
        xyz="0 0 0"
        rpy="0 0 0" />
      <geometry>
        <mesh
          filename="meshes/left_ankle_pitch_link.STL" />
      </geometry>
    </collision> -->
  </link>
  <joint
    name="left_ankle_pitch_joint"
    type="revolute">
    <origin
      xyz="0 0 -0.3"
      rpy="0 0 0" />
    <parent
      link="left_knee_pitch_link" />
    <child
      link="left_ankle_pitch_link" />
    <axis
      xyz="0 1 0" />
    <limit
      lower="-0.87267"
      upper="0.5236"
      effort="36"
      velocity="3.6" />
  </joint>
  <link
    name="left_ankle_roll_link">
    <inertial>
      <origin
        xyz="0.018367 0 -0.022988"
        rpy="0 0 0" />
      <mass
        value="1.01" />
      <!-- <inertia
        ixx="0.00084643"
        ixy="0"
        ixz="0.00030134"
        iyy="0.0038841"
        iyz="0"
        izz="0.004139" />
    </inertial> -->
    <inertia ixx="0.01" ixy="2E-07" ixz="8.91E-05" iyy="0.01" iyz="-1E-07" izz="0.01"/></inertial>
    <visual>
      <origin
        xyz="0 0 0"
        rpy="0 0 0" />
      <geometry>
        <mesh
          filename="meshes/left_ankle_roll_link.STL" />
      </geometry>
      <material
        name="">
        <color
          rgba="0.69804 0.69804 0.69804 1" />
      </material>
    </visual>
    <collision>
      <origin
        xyz="0 0 0"
        rpy="0 0 0" />
      <geometry>
        <mesh
          filename="meshes/left_ankle_roll_link.STL" />
      </geometry>
    </collision>
    <!-- <collision>
      <origin xyz="0.0925 0.0 -0.038" rpy="0 0 0"/>
      <geometry>
        <box size="0.11 0.10 0.015"/>
      </geometry>
    </collision>

    <collision>
      <origin xyz="-0.0285 0.0 -0.038" rpy="0 0 0"/>
      <geometry>
        <box size="0.13 0.08 0.015"/>
      </geometry>
    </collision> -->
  </link>
  <joint
    name="left_ankle_roll_joint"
    type="revolute">
    <origin
      xyz="0 0 0"
      rpy="0 0 0" />
    <parent
      link="left_ankle_pitch_link" />
    <child
      link="left_ankle_roll_link" />
    <axis
      xyz="1 0 0" />
    <limit
      lower="-0.349"
      upper="0.349"
      effort="36"
      velocity="3.6" />
  </joint>
  <link
    name="right_leg_pitch_link">
    <inertial>
      <origin
        xyz="-0.0022424 -0.052767 0.0018571"
        rpy="0 0 0" />
      <mass
        value="1.06" />
      <inertia
        ixx="0.0019426"
        ixy="-2.473E-05"
        ixz="-4.36E-06"
        iyy="0.0012366"
        iyz="-4.201E-05"
        izz="0.0015442" />
    </inertial>
    <visual>
      <origin
        xyz="0 0 0"
        rpy="0 0 0" />
      <geometry>
        <mesh
          filename="meshes/right_leg_pitch_link.STL" />
      </geometry>
      <material
        name="">
        <color
          rgba="0.69804 0.69804 0.69804 1" />
      </material>
    </visual>
    <!-- <collision>
      <origin
        xyz="0 0 0"
        rpy="0 0 0" />
      <geometry>
        <mesh
          filename="meshes/right_leg_pitch_link.STL" />
      </geometry>
    </collision> -->
  </link>
  <joint
    name="right_leg_pitch_joint"
    type="revolute">
    <origin
      xyz="0 -0.057 -0.06025"
      rpy="0 0 0" />
    <parent
      link="pelvis" />
    <child
      link="right_leg_pitch_link" />
    <axis
      xyz="0 1 0" />
    <limit
      lower="-2.792"
      upper="2.792"
      effort="90"
      velocity="9" />
  </joint>
  <link
    name="right_leg_roll_link">
    <inertial>
      <origin
        xyz="0.002441 3.17E-05 -0.092183"
        rpy="0 0 0" />
      <mass
        value="0.8" />
      <inertia
        ixx="0.0015404"
        ixy="2.5E-07"
        ixz="-0.0001421"
        iyy="0.001629"
        iyz="-3E-08"
        izz="0.00094122" />
    </inertial>
    <visual>
      <origin
        xyz="0 0 0"
        rpy="0 0 0" />
      <geometry>
        <mesh
          filename="meshes/right_leg_roll_link.STL" />
      </geometry>
      <material
        name="">
        <color
          rgba="0.69804 0.69804 0.69804 1" />
      </material>
    </visual>
    <collision>
      <origin
        xyz="0 0 0"
        rpy="0 0 0" />
      <geometry>
        <mesh
          filename="meshes/right_leg_roll_link.STL" />
      </geometry>
    </collision>
  </link>
  <joint
    name="right_leg_roll_joint"
    type="revolute">
    <origin
      xyz="0 -0.06 0"
      rpy="0 0 0" />
    <parent
      link="right_leg_pitch_link" />
    <child
      link="right_leg_roll_link" />
    <axis
      xyz="1 0 0" />
    <limit
      lower="-3.037"
      upper="0.087"
      effort="90"
      velocity="9" />
  </joint>
  <link
    name="right_leg_yaw_link">
    <inertial>
      <origin
        xyz="0.0010862 0.00087371 -0.15709"
        rpy="0 0 0" />
      <mass
        value="2.93" />
      <inertia
        ixx="0.0082847"
        ixy="2.33E-06"
        ixz="-0.00032892"
        iyy="0.009843"
        iyz="1.188E-05"
        izz="0.0036644" />
    </inertial>
    <visual>
      <origin
        xyz="0 0 0"
        rpy="0 0 0" />
      <geometry>
        <mesh
          filename="meshes/right_leg_yaw_link.STL" />
      </geometry>
      <material
        name="">
        <color
          rgba="0.69804 0.69804 0.69804 1" />
      </material>
    </visual>
    <!-- <collision>
      <origin
        xyz="0 0 0.06"
        rpy="0 0 0" />
      <geometry>
        <box size="0.11 0.11 0.15" />
      </geometry>
    </collision> -->
    <collision>
      <origin
        xyz="0 0 0"
        rpy="0 0 0" />
      <geometry>
        <mesh
          filename="meshes/right_leg_yaw_link.STL" />
      </geometry>
    </collision>
  </link>
  <joint
    name="right_leg_yaw_joint"
    type="revolute">
    <origin
      xyz="0 0 -0.127"
      rpy="0 0 0" />
    <parent
      link="right_leg_roll_link" />
    <child
      link="right_leg_yaw_link" />
    <axis
      xyz="0 0 1" />
    <limit
      lower="-2.269"
      upper="2.269"
      effort="60"
      velocity="6" />
  </joint>
  <link
    name="right_knee_pitch_link">
    <inertial>
      <origin
        xyz="-0.0032204 -0.0014598 -0.13449"
        rpy="0 0 0" />
      <mass
        value="2.19" />
      <inertia
        ixx="0.016812"
        ixy="1.207E-05"
        ixz="-0.00040801"
        iyy="0.017943"
        iyz="0.00098645"
        izz="0.0029855" />
    </inertial>
    <visual>
      <origin
        xyz="0 0 0"
        rpy="0 0 0" />
      <geometry>
        <mesh
          filename="meshes/right_knee_pitch_link.STL" />
      </geometry>
      <material
        name="">
        <color
          rgba="0.89804 0.91373 0.92549 1" />
      </material>
    </visual>
    <collision>
      <origin
        xyz="0 0 -0.13"
        rpy="0 0 0" />
      <geometry>
        <box size="0.13 0.07 0.14" />
      </geometry>
    </collision>
    <!-- <collision>
      <origin
        xyz="0 0 0"
        rpy="0 0 0" />
      <geometry>
        <mesh
          filename="meshes/right_knee_pitch_link.STL" />
      </geometry>
    </collision> -->
  </link>
  <joint
    name="right_knee_pitch_joint"
    type="revolute">
    <origin
      xyz="0 0 -0.173"
      rpy="0 0 0" />
    <parent
      link="right_leg_yaw_link" />
    <child
      link="right_knee_pitch_link" />
    <axis
      xyz="0 1 0" />
    <limit
      lower="-0.052"
      upper="2.618"
      effort="150"
      velocity="15" />
  </joint>
  <link
    name="right_ankle_pitch_link">
    <inertial>
      <origin
        xyz="0 0 0"
        rpy="0 0 0" />
      <mass
        value="0.16" />
      <!-- <inertia
        ixx="0.00010835"
        ixy="0"
        ixz="0"
        iyy="5.9E-06"
        iyz="0"
        izz="0.00010835" />
    </inertial> -->
    <inertia ixx="0.03" ixy="0" ixz="0" iyy="0.03" iyz="0" izz="0.03"/> </inertial>
    <visual>
      <origin
        xyz="0 0 0"
        rpy="0 0 0" />
      <geometry>
        <mesh
          filename="meshes/right_ankle_pitch_link.STL" />
      </geometry>
      <material
        name="">
        <color
          rgba="0.69804 0.69804 0.69804 1" />
      </material>
    </visual>
    <!-- <collision>
      <origin
        xyz="0 0 0"
        rpy="0 0 0" />
      <geometry>
        <mesh
          filename="meshes/right_ankle_pitch_link.STL" />
      </geometry>
    </collision> -->
  </link>
  <joint
    name="right_ankle_pitch_joint"
    type="revolute">
    <origin
      xyz="0 0 -0.3"
      rpy="0 0 0" />
    <parent
      link="right_knee_pitch_link" />
    <child
      link="right_ankle_pitch_link" />
    <axis
      xyz="0 1 0" />
    <limit
      lower="-0.87267"
      upper="0.5236"
      effort="36"
      velocity="3.6" />
  </joint>
  <link
    name="right_ankle_roll_link">
    <inertial>
      <origin
        xyz="0.018366 0 -0.023002"
        rpy="0 0 0" />
      <mass
        value="1.01" />
      <!-- <inertia
        ixx="0.00084333"
        ixy="0"
        ixz="0.00030008"
        iyy="0.0038735"
        iyz="0"
        izz="0.0041281" />
    </inertial> -->
    <inertia ixx="0.01" ixy="2E-07" ixz="8.91E-05" iyy="0.01" iyz="-1E-07" izz="0.01"/></inertial>
    <visual>
      <origin
        xyz="0 0 0"
        rpy="0 0 0" />
      <geometry>
        <mesh
          filename="meshes/right_ankle_roll_link.STL" />
      </geometry>
      <material
        name="">
        <color
          rgba="0.69804 0.69804 0.69804 1" />
      </material>
    </visual>
    <collision>
      <origin
        xyz="0 0 0"
        rpy="0 0 0" />
      <geometry>
        <mesh
          filename="meshes/right_ankle_roll_link.STL" />
      </geometry>
    </collision>

    <!-- <collision>
      <origin xyz="0.0925 0.0 -0.038" rpy="0 0 0"/>
      <geometry>
        <box size="0.11 0.10 0.015"/>
      </geometry>
    </collision>

    <collision>
      <origin xyz="-0.0285 0.0 -0.038" rpy="0 0 0"/>
      <geometry>
        <box size="0.13 0.08 0.015"/>
      </geometry>
    </collision> -->
  </link>

  <joint
    name="right_ankle_roll_joint"
    type="revolute">
    <origin
      xyz="0 0 0"
      rpy="0 0 0" />
    <parent
      link="right_ankle_pitch_link" />
    <child
      link="right_ankle_roll_link" />
    <axis
      xyz="1 0 0" />
    <limit
      lower="-0.349"
      upper="0.349"
      effort="36"
      velocity="3.6" />
  </joint>
  <link
    name="torso_link">
    <inertial>
      <origin
        xyz="-2.98E-06 8.41E-06 0.25361"
        rpy="0 0 0" />
      <mass
        value="2.6616" />
      <inertia
        ixx="0.035915"
        ixy="-2.1E-07"
        ixz="1.903E-05"
        iyy="0.030172"
        iyz="1.15E-06"
        izz="0.007787" />
    </inertial>
    <visual>
      <origin
        xyz="0 0 0"
        rpy="0 0 0" />
      <geometry>
        <mesh
          filename="meshes/waist_yaw_link.STL" />
      </geometry>
      <material
        name="">
        <color
          rgba="0.69804 0.69804 0.69804 1" />
      </material>
    </visual>
    <!-- <collision>
      <origin
        xyz="0 0 0"
        rpy="0 0 0" />
      <geometry>
        <mesh
          filename="meshes/waist_yaw_link.STL" />
      </geometry>
    </collision> -->
    <collision>
      <origin
        xyz="0 0 0.15"
        rpy="0 0 0" />
      <geometry>
        <box size="0.1 0.15 0.2"/>
      </geometry>
    </collision>
  </link>
  <joint
    name="waist_yaw_joint"
    type="fixed"
    dont_collapse="true">
    <origin
      xyz="0 0 0.05725"
      rpy="0 0 0" />
    <parent
      link="pelvis" />
    <child
      link="torso_link" />
    <axis
      xyz="0 0 1" />
    <limit
      lower="-0.96"
      upper="0.96"
      effort="90"
      velocity="9" />
  </joint>
  <link
    name="left_shoulder_pitch_link">
    <inertial>
      <origin
        xyz="0.0074125 0.055258 2.03E-05"
        rpy="0 0 0" />
      <mass
        value="0.51" />
      <inertia
        ixx="0.00040726"
        ixy="-2.257E-05"
        ixz="1.7E-07"
        iyy="0.00033867"
        iyz="-2.1E-07"
        izz="0.00048429" />
    </inertial>
    <visual>
      <origin
        xyz="0 0 0"
        rpy="0 0 0" />
      <geometry>
        <mesh
          filename="meshes/left_shoulder_pitch_link.STL" />
      </geometry>
      <material
        name="">
        <color
          rgba="0.69804 0.69804 0.69804 1" />
      </material>
    </visual>
    <!-- <collision>
      <origin
        xyz="0 0 0"
        rpy="0 0 0" />
      <geometry>
        <mesh
          filename="meshes/left_shoulder_pitch_link.STL" />
      </geometry>
    </collision> -->
  </link>
  <joint
    name="left_shoulder_pitch_joint"
    type="revolute">
    <origin
      xyz="0 0.079102 0.32072"
      rpy="0.2618 0 0" />
    <parent
      link="torso_link" />
    <child
      link="left_shoulder_pitch_link" />
    <axis
      xyz="0 1 0" />
    <limit
      lower="-1.57"
      upper="1.57"
      effort="60"
      velocity="6" />
  </joint>
  <link
    name="left_shoulder_roll_link">
    <inertial>
      <origin
        xyz="0.0084543 -7.54E-06 -0.073356"
        rpy="0 0 0" />
      <mass
        value="0.64" />
      <inertia
        ixx="0.00064086"
        ixy="-1.5E-07"
        ixz="-0.00014778"
        iyy="0.00071374"
        iyz="-3E-08"
        izz="0.00039867" />
    </inertial>
    <visual>
      <origin
        xyz="0 0 0"
        rpy="0 0 0" />
      <geometry>
        <mesh
          filename="meshes/left_shoulder_roll_link.STL" />
      </geometry>
      <material
        name="">
        <color
          rgba="0.69804 0.69804 0.69804 1" />
      </material>
    </visual>
    <!-- <collision>
      <origin
        xyz="0 0 0"
        rpy="0 0 0" />
      <geometry>
        <mesh
          filename="meshes/left_shoulder_roll_link.STL" />
      </geometry>
    </collision> -->
  </link>
  <joint
    name="left_shoulder_roll_joint"
    type="fixed">
    <origin
      xyz="0 0.064 0"
      rpy="-0.2618 0 0" />
    <parent
      link="left_shoulder_pitch_link" />
    <child
      link="left_shoulder_roll_link" />
    <axis
      xyz="1 0 0" />
    <limit
      lower="-0.1"
      upper="3.14"
      effort="36"
      velocity="3.6" />
  </joint>
  <link
    name="left_shoulder_yaw_link">
    <inertial>
      <origin
        xyz="-0.00056928 0.0074854 -0.089061"
        rpy="0 0 0" />
      <mass
        value="0.49" />
      <inertia
        ixx="0.0005398"
        ixy="-1.44E-06"
        ixz="9.38E-06"
        iyy="0.00046638"
        iyz="3.104E-05"
        izz="0.00032516" />
    </inertial>
    <visual>
      <origin
        xyz="0 0 0"
        rpy="0 0 0" />
      <geometry>
        <mesh
          filename="meshes/left_shoulder_yaw_link.STL" />
      </geometry>
      <material
        name="">
        <color
          rgba="0.69804 0.69804 0.69804 1" />
      </material>
    </visual>
    <!-- <collision>
      <origin
        xyz="0 0 0"
        rpy="0 0 0" />
      <geometry>
        <mesh
          filename="meshes/left_shoulder_yaw_link.STL" />
      </geometry>
    </collision> -->
  </link>
  <joint
    name="left_shoulder_yaw_joint"
    type="fixed">
    <origin
      xyz="0.00013761 0 -0.103"
      rpy="0 0 0" />
    <parent
      link="left_shoulder_roll_link" />
    <child
      link="left_shoulder_yaw_link" />
    <axis
      xyz="0 0 1" />
    <limit
      lower="-1.57"
      upper="1.57"
      effort="36"
      velocity="3.6" />
  </joint>
  <link
    name="left_elbow_pitch_link">
    <inertial>
      <origin
        xyz="0.073356 0.0084377 7.54E-06"
        rpy="0 0 0" />
      <mass
        value="0.64" />
      <inertia
        ixx="0.00039885"
        ixy="0.00014808"
        ixz="-3E-08"
        iyy="0.00064086"
        iyz="1.5E-07"
        izz="0.00071392" />
    </inertial>
    <visual>
      <origin
        xyz="0 0 0"
        rpy="0 0 0" />
      <geometry>
        <mesh
          filename="meshes/left_elbow_pitch_link.STL" />
      </geometry>
      <material
        name="">
        <color
          rgba="0.69804 0.69804 0.69804 1" />
      </material>
    </visual>
    <collision>
      <origin
        xyz="0 0 0"
        rpy="0 0 0" />
      <geometry>
        <mesh
          filename="meshes/left_elbow_pitch_link.STL" />
      </geometry>
    </collision>
  </link>
  <joint
    name="left_elbow_pitch_joint"
    type="revolute">
    <origin
      xyz="-0.00013761 0 -0.097"
      rpy="0 0 0" />
    <parent
      link="left_shoulder_yaw_link" />
    <child
      link="left_elbow_pitch_link" />
    <axis
      xyz="0 1 0" />
    <limit
      lower="-1.57"
      upper="1.57"
      effort="36"
      velocity="3.6" />
  </joint>
  <link
    name="left_elbow_roll_link">
    <inertial>
      <origin
        xyz="0.041845 0.0052481 0.00015646"
        rpy="0 0 0" />
      <mass
        value="0.45701" />
      <inertia
        ixx="0.00015637"
        ixy="-1.75E-06"
        ixz="-2E-08"
        iyy="0.00018977"
        iyz="-1.43E-06"
        izz="0.00020277" />
    </inertial>
    <visual>
      <origin
        xyz="0 0 0"
        rpy="0 0 0" />
      <geometry>
        <mesh
          filename="meshes/left_elbow_roll_link.STL" />
      </geometry>
      <material
        name="">
        <color
          rgba="0.69804 0.69804 0.69804 1" />
      </material>
    </visual>
    <!-- <collision>
      <origin
        xyz="0 0 0"
        rpy="0 0 0" />
      <geometry>
        <mesh
          filename="meshes/left_elbow_roll_link.STL" />
      </geometry>
    </collision> -->
  </link>
  <joint
    name="left_elbow_roll_joint"
    type="fixed">
    <origin
      xyz="0.103 -0.00013761 0"
      rpy="0 0 0" />
    <parent
      link="left_elbow_pitch_link" />
    <child
      link="left_elbow_roll_link" />
    <axis
      xyz="1 0 0" />
    <limit
      lower="-1.57"
      upper="1.57"
      effort="36"
      velocity="3.6" />
  </joint>
  <link
    name="left_wrist_pitch_link">
    <inertial>
      <origin
        xyz="-3.08E-06 7.559E-05 0.0057017"
        rpy="0 0 0" />
      <mass
        value="0.43" />
      <inertia
        ixx="0.00014047"
        ixy="1E-08"
        ixz="2E-08"
        iyy="0.00013372"
        iyz="-4.7E-07"
        izz="0.00014818" />
    </inertial>
    <visual>
      <origin
        xyz="0 0 0"
        rpy="0 0 0" />
      <geometry>
        <mesh
          filename="meshes/left_wrist_pitch_link.STL" />
      </geometry>
      <material
        name="">
        <color
          rgba="0.69804 0.69804 0.69804 1" />
      </material>
    </visual>
    <!-- <collision>
      <origin
        xyz="0 0 0"
        rpy="0 0 0" />
      <geometry>
        <mesh
          filename="meshes/left_wrist_pitch_link.STL" />
      </geometry>
    </collision> -->
  </link>
  <joint
    name="left_wrist_pitch_joint"
    type="fixed">
    <origin
      xyz="0.097 0.00013761 0"
      rpy="0 0 0" />
    <parent
      link="left_elbow_roll_link" />
    <child
      link="left_wrist_pitch_link" />
    <axis
      xyz="0 1 0" />
    <limit
      lower="-1.57"
      upper="1.57"
      effort="36"
      velocity="3.6" />
  </joint>
  <link
    name="left_wrist_yaw_link">
    <inertial>
      <origin
        xyz="0.10225 -0.0074062 0.0096664"
        rpy="0 0 0" />
      <mass
        value="0.55" />
      <inertia
        ixx="0.0005972"
        ixy="-4.9E-05"
        ixz="0.00012376"
        iyy="0.0017704"
        iyz="0.00017739"
        izz="0.0015946" />
    </inertial>
    <visual>
      <origin
        xyz="0 0 0"
        rpy="0 0 0" />
      <geometry>
        <mesh
          filename="meshes/left_wrist_yaw_link.STL" />
      </geometry>
      <material
        name="">
        <color
          rgba="1 1 1 1" />
      </material>
    </visual>
    <collision>
      <origin
        xyz="0 0 0"
        rpy="0 0 0" />
      <geometry>
        <mesh
          filename="meshes/left_wrist_yaw_link.STL" />
      </geometry>
    </collision>
  </link>
  <joint
    name="left_wrist_yaw_joint"
    type="fixed">
    <origin
      xyz="0 0 0"
      rpy="0 0 0" />
    <parent
      link="left_wrist_pitch_link" />
    <child
      link="left_wrist_yaw_link" />
    <axis
      xyz="0 0 1" />
    <limit
      lower="-1.57"
      upper="1.57"
      effort="36"
      velocity="3.6" />
  </joint>
  <link
    name="right_shoulder_pitch_link">
    <inertial>
      <origin
        xyz="0.0074125 -0.055258 1.602E-05"
        rpy="0 0 0" />
      <mass
        value="0.51" />
      <inertia
        ixx="0.00040726"
        ixy="2.257E-05"
        ixz="-2.2E-07"
        iyy="0.00033867"
        iyz="-1.8E-07"
        izz="0.00048429" />
    </inertial>
    <visual>
      <origin
        xyz="0 0 0"
        rpy="0 0 0" />
      <geometry>
        <mesh
          filename="meshes/right_shoulder_pitch_link.STL" />
      </geometry>
      <material
        name="">
        <color
          rgba="0.69804 0.69804 0.69804 1" />
      </material>
    </visual>
    <!-- <collision>
      <origin
        xyz="0 0 0"
        rpy="0 0 0" />
      <geometry>
        <mesh
          filename="meshes/right_shoulder_pitch_link.STL" />
      </geometry>
    </collision> -->
  </link>
  <joint
    name="right_shoulder_pitch_joint"
    type="revolute">
    <origin
      xyz="0 -0.079102 0.32072"
      rpy="-0.2618 0 0" />
    <parent
      link="torso_link" />
    <child
      link="right_shoulder_pitch_link" />
    <axis
      xyz="0 1 0" />
    <limit
      lower="-1.57"
      upper="1.57"
      effort="60"
      velocity="6" />
  </joint>
  <link
    name="right_shoulder_roll_link">
    <inertial>
      <origin
        xyz="0.0084253 7.69E-06 -0.073356"
        rpy="0 0 0" />
      <mass
        value="0.64" />
      <inertia
        ixx="0.00064086"
        ixy="-7E-08"
        ixz="-0.00014751"
        iyy="0.00071406"
        iyz="3E-08"
        izz="0.00039899" />
    </inertial>
    <visual>
      <origin
        xyz="0 0 0"
        rpy="0 0 0" />
      <geometry>
        <mesh
          filename="meshes/right_shoulder_roll_link.STL" />
      </geometry>
      <material
        name="">
        <color
          rgba="0.69804 0.69804 0.69804 1" />
      </material>
    </visual>
    <!-- <collision>
      <origin
        xyz="0 0 0"
        rpy="0 0 0" />
      <geometry>
        <mesh
          filename="meshes/right_shoulder_roll_link.STL" />
      </geometry>
    </collision> -->
  </link>
  <joint
    name="right_shoulder_roll_joint"
    type="fixed">
    <origin
      xyz="0 -0.064 0"
      rpy="0.2618 0 0" />
    <parent
      link="right_shoulder_pitch_link" />
    <child
      link="right_shoulder_roll_link" />
    <axis
      xyz="1 0 0" />
    <limit
      lower="-3.14"
      upper="0.1"
      effort="36"
      velocity="3.6" />
  </joint>
  <link
    name="right_shoulder_yaw_link">
    <inertial>
      <origin
        xyz="-0.00056932 -0.0074855 -0.089041"
        rpy="0 0 0" />
      <mass
        value="0.49" />
      <inertia
        ixx="0.00053964"
        ixy="1.44E-06"
        ixz="9.6E-06"
        iyy="0.00046622"
        iyz="-3.104E-05"
        izz="0.00032516" />
    </inertial>
    <visual>
      <origin
        xyz="0 0 0"
        rpy="0 0 0" />
      <geometry>
        <mesh
          filename="meshes/right_shoulder_yaw_link.STL" />
      </geometry>
      <material
        name="">
        <color
          rgba="0.69804 0.69804 0.69804 1" />
      </material>
    </visual>
    <!-- <collision>
      <origin
        xyz="0 0 0"
        rpy="0 0 0" />
      <geometry>
        <mesh
          filename="meshes/right_shoulder_yaw_link.STL" />
      </geometry>
    </collision> -->
  </link>
  <joint
    name="right_shoulder_yaw_joint"
    type="fixed">
    <origin
      xyz="0.00013761 0 -0.103"
      rpy="0 0 0" />
    <parent
      link="right_shoulder_roll_link" />
    <child
      link="right_shoulder_yaw_link" />
    <axis
      xyz="0 0 1" />
    <limit
      lower="-1.57"
      upper="1.57"
      effort="36"
      velocity="3.6" />
  </joint>
  <link
    name="right_elbow_pitch_link">
    <inertial>
      <origin
        xyz="0.073356 -0.0084377 -7.54E-06"
        rpy="0 0 0" />
      <mass
        value="0.64" />
      <inertia
        ixx="0.00039885"
        ixy="-0.00014808"
        ixz="3E-08"
        iyy="0.00064086"
        iyz="1.5E-07"
        izz="0.00071392" />
    </inertial>
    <visual>
      <origin
        xyz="0 0 0"
        rpy="0 0 0" />
      <geometry>
        <mesh
          filename="meshes/right_elbow_pitch_link.STL" />
      </geometry>
      <material
        name="">
        <color
          rgba="0.77255 0.75294 0.73333 1" />
      </material>
    </visual>
    <collision>
      <origin
        xyz="0 0 0"
        rpy="0 0 0" />
      <geometry>
        <mesh
          filename="meshes/right_elbow_pitch_link.STL" />
      </geometry>
    </collision>
  </link>
  <joint
    name="right_elbow_pitch_joint"
    type="revolute">
    <origin
      xyz="-0.00013761 0 -0.097"
      rpy="0 0 0" />
    <parent
      link="right_shoulder_yaw_link" />
    <child
      link="right_elbow_pitch_link" />
    <axis
      xyz="0 1 0" />
    <limit
      lower="-1.57"
      upper="1.57"
      effort="36"
      velocity="3.6" />
  </joint>
  <link
    name="right_elbow_roll_link">
    <inertial>
      <origin
        xyz="0.041845 -0.0052481 0.00015645"
        rpy="0 0 0" />
      <mass
        value="0.45701" />
      <inertia
        ixx="0.00015637"
        ixy="1.75E-06"
        ixz="-2E-08"
        iyy="0.00018977"
        iyz="1.43E-06"
        izz="0.00020277" />
    </inertial>
    <visual>
      <origin
        xyz="0 0 0"
        rpy="0 0 0" />
      <geometry>
        <mesh
          filename="meshes/right_elbow_roll_link.STL" />
      </geometry>
      <material
        name="">
        <color
          rgba="0.69804 0.69804 0.69804 1" />
      </material>
    </visual>
    <!-- <collision>
      <origin
        xyz="0 0 0"
        rpy="0 0 0" />
      <geometry>
        <mesh
          filename="meshes/right_elbow_roll_link.STL" />
      </geometry>
    </collision> -->
  </link>
  <joint
    name="right_elbow_roll_joint"
    type="fixed">
    <origin
      xyz="0.103 0.00013761 0"
      rpy="0 0 0" />
    <parent
      link="right_elbow_pitch_link" />
    <child
      link="right_elbow_roll_link" />
    <axis
      xyz="1 0 0" />
    <limit
      lower="-1.57"
      upper="1.57"
      effort="36"
      velocity="3.6" />
  </joint>
  <link
    name="right_wrist_pitch_link">
    <inertial>
      <origin
        xyz="-3.09E-06 -7.559E-05 0.0057017"
        rpy="0 0 0" />
      <mass
        value="0.43" />
      <inertia
        ixx="0.00014047"
        ixy="-1E-08"
        ixz="2E-08"
        iyy="0.00013372"
        iyz="4.7E-07"
        izz="0.00014818" />
    </inertial>
    <visual>
      <origin
        xyz="0 0 0"
        rpy="0 0 0" />
      <geometry>
        <mesh
          filename="meshes/right_wrist_pitch_link.STL" />
      </geometry>
      <material
        name="">
        <color
          rgba="0.89804 0.91373 0.92549 1" />
      </material>
    </visual>
    <!-- <collision>
      <origin
        xyz="0 0 0"
        rpy="0 0 0" />
      <geometry>
        <mesh
          filename="meshes/right_wrist_pitch_link.STL" />
      </geometry>
    </collision> -->
  </link>
  <joint
    name="right_wrist_pitch_joint"
    type="fixed">
    <origin
      xyz="0.097 -0.00013761 0"
      rpy="0 0 0" />
    <parent
      link="right_elbow_roll_link" />
    <child
      link="right_wrist_pitch_link" />
    <axis
      xyz="0 1 0" />
    <limit
      lower="-1.57"
      upper="1.57"
      effort="36"
      velocity="3.6" />
  </joint>
  <link
    name="right_wrist_yaw_link">
    <inertial>
      <origin
        xyz="0.10225295 0.00741158 0.00966516"
        rpy="0 0 0" />
      <mass
        value="0.55" />
      <inertia
        ixx="0.00059718"
        ixy="4.9E-05"
        ixz="0.00012377"
        iyy="0.00177048"
        iyz="-0.00017741"
        izz="0.00159457" />
    </inertial>
    <visual>
      <origin
        xyz="0 0 0"
        rpy="0 0 0" />
      <geometry>
        <mesh
          filename="meshes/right_wrist_yaw_link.STL" />
      </geometry>
      <material
        name="">
        <color
          rgba="0.89804 0.91373 0.92549 1" />
      </material>
    </visual>
    <collision>
      <origin
        xyz="0 0 0"
        rpy="0 0 0" />
      <geometry>
        <mesh
          filename="meshes/right_wrist_yaw_link.STL" />
      </geometry>
    </collision>
  </link>
  <joint
    name="right_wrist_yaw_joint"
    type="fixed">
    <origin
      xyz="0 0 0"
      rpy="0 0 0" />
    <parent
      link="right_wrist_pitch_link" />
    <child
      link="right_wrist_yaw_link" />
    <axis
      xyz="0 0 1" />
    <limit
      lower="-1.57"
      upper="1.57"
      effort="36"
      velocity="3.6" />
  </joint>
  <link
    name="neck_yaw_link">
    <inertial>
      <origin
        xyz="2E-05 -0.0078274 0.10031"
        rpy="0 0 0" />
      <mass
        value="0.45" />
      <inertia
        ixx="0.0004581"
        ixy="-2E-07"
        ixz="4E-08"
        iyy="0.00038248"
        iyz="1.86E-05"
        izz="0.00030042" />
    </inertial>
    <visual>
      <origin
        xyz="0 0 0"
        rpy="0 0 0" />
      <geometry>
        <mesh
          filename="meshes/neck_yaw_link.STL" />
      </geometry>
      <material
        name="">
        <color
          rgba="0.77255 0.75294 0.73333 1" />
      </material>
    </visual>
    <!-- <collision>
      <origin
        xyz="0 0 0"
        rpy="0 0 0" />
      <geometry>
        <mesh
          filename="meshes/neck_yaw_link.STL" />
      </geometry>
    </collision> -->
  </link>
  <joint
    name="neck_yaw_joint"
    type="fixed">
    <origin
      xyz="0 0 0.30273"
      rpy="0 0 0" />
    <parent
      link="torso_link" />
    <child
      link="neck_yaw_link" />
    <axis
      xyz="0 0 1" />
    <limit
      lower="-0.2"
      upper="0.2"
      effort="36"
      velocity="3.6" />
  </joint>
  <link
    name="neck_pitch_link">
    <inertial>
      <origin
        xyz="0.05962 0.029873 0.10199"
        rpy="0 0 0" />
      <mass
        value="1.21" />
      <inertia
        ixx="0.001667"
        ixy="-9.013E-05"
        ixz="-0.00018388"
        iyy="0.00099997"
        iyz="-8.096E-05"
        izz="0.0021611" />
    </inertial>
    <visual>
      <origin
        xyz="0 0 0"
        rpy="0 0 0" />
      <geometry>
        <mesh
          filename="meshes/neck_pitch_link.STL" />
      </geometry>
      <material
        name="">
        <color
          rgba="0.69804 0.69804 0.69804 1" />
      </material>
    </visual>
    <!-- <collision>
      <origin
        xyz="0 0 0"
        rpy="0 0 0" />
      <geometry>
        <mesh
          filename="meshes/neck_pitch_link.STL" />
      </geometry>
    </collision> -->
  </link>
  <joint
    name="neck_pitch_joint"
    type="fixed">
    <origin
      xyz="-1.26E-05 -0.031 0.10591"
      rpy="0 0 0" />
    <parent
      link="neck_yaw_link" />
    <child
      link="neck_pitch_link" />
    <axis
      xyz="0 1 0" />
    <limit
      lower="-0.2"
      upper="0.2"
      effort="36"
      velocity="3.6" />
  </joint>

  <link name="imu_in_torso">
    <!-- <visual>
      <origin xyz="0 0 0" rpy="0 0 0" />
      <geometry>
        <sphere radius="0.005"/>
      </geometry>
      <material name="red">
        <color rgba="1 0 0 1"/>  
      </material>
    </visual> -->
  </link>
  <joint name="imu_in_torso_joint" type="fixed">
    <origin xyz="-0.00 -0.0024 0.02092" rpy="0 0 0"/>
    <parent link="torso_link"/>
    <child link="imu_in_torso"/>
  </joint>

  <link name="imu_in_pelvis">
    <!-- <visual>
      <origin xyz="0 0 0" rpy="0 0 0" />
      <geometry>
        <sphere radius="0.005"/>
      </geometry>
      <material name="red">
        <color rgba="1 0 0 1"/>  
      </material>
    </visual> -->
  </link>

  <joint name="imu_in_pelvis_joint" type="fixed">
    <origin xyz="0.00525 0 -0.00339" rpy="0 0 0"/>
    <parent link="pelvis"/>
    <child link="imu_in_pelvis"/>
  </joint>

  <!-- d435 -->
  <link name="d435_link">
    <!-- <visual>
      <origin xyz="0 0 0" rpy="0 0 0" />
      <geometry>
        <sphere radius="0.005"/>
      </geometry>
      <material name="red">
        <color rgba="1 0 0 1"/>  
      </material>
    </visual> -->
  </link>
  <joint name="d435_joint" type="fixed">
    <origin xyz="0.0576235 0.01753 0.50987" rpy="0 0.8307767239493009 0"/>
    <parent link="torso_link"/>
    <child link="d435_link"/>
  </joint>

  <!-- mid360 -->
  <link name="mid360_link">
    <!-- <visual>
      <origin xyz="0 0 0" rpy="0 0 0" />
      <geometry>
        <sphere radius="0.005"/>
      </geometry>
      <material name="red">
        <color rgba="1 0 0 1"/>  
      </material>
    </visual> -->
  </link>
  <joint name="mid360_joint" type="fixed">
    <origin xyz="0.0002835 0.00003 0.501618" rpy="0 0.04014257279586953 0"/>
    <parent link="torso_link"/>
    <child link="mid360_link"/>
  </joint>


</robot>