<mujoco model="ym1_16dof">
  <compiler angle="radian" meshdir="meshes" autolimits="true"/>

  <option iterations='50' solver='PGS' gravity='0 0 -9.81'>
    <flag frictionloss="enable"/>
  </option>
    
  <default>
    <joint damping="0.001" armature="0.01" frictionloss="0.1"/>
  </default>

  <asset>
    <mesh name="pelvis" file="base_link.STL"/>
    <mesh name="torso" file="waist_yaw_link.STL"/>
    <mesh name="left_leg_pitch_link" file="left_leg_pitch_link.STL"/>
    <mesh name="left_leg_roll_link" file="left_leg_roll_link.STL"/>
    <mesh name="left_leg_yaw_link" file="left_leg_yaw_link.STL"/>
    <mesh name="left_knee_pitch_link" file="left_knee_pitch_link.STL"/>
    <mesh name="left_ankle_pitch_link" file="left_ankle_pitch_link.STL"/>
    <mesh name="left_ankle_roll_link" file="left_ankle_roll_link.STL"/>
    <mesh name="right_leg_pitch_link" file="right_leg_pitch_link.STL"/>
    <mesh name="right_leg_roll_link" file="right_leg_roll_link.STL"/>
    <mesh name="right_leg_yaw_link" file="right_leg_yaw_link.STL"/>
    <mesh name="right_knee_pitch_link" file="right_knee_pitch_link.STL"/>
    <mesh name="right_ankle_pitch_link" file="right_ankle_pitch_link.STL"/>
    <mesh name="right_ankle_roll_link" file="right_ankle_roll_link.STL"/>
    <mesh name="left_shoulder_pitch_link" file="left_shoulder_pitch_link.STL"/>
    <mesh name="left_shoulder_roll_link" file="left_shoulder_roll_link.STL"/>
    <mesh name="left_shoulder_yaw_link" file="left_shoulder_yaw_link.STL"/>
    <mesh name="left_elbow_pitch_link" file="left_elbow_pitch_link.STL"/>
    <mesh name="left_elbow_roll_link" file="left_elbow_roll_link.STL"/>
    <mesh name="left_wrist_pitch_link" file="left_wrist_pitch_link.STL"/>
    <mesh name="left_wrist_yaw_link" file="left_wrist_yaw_link.STL"/>
    <mesh name="right_shoulder_pitch_link" file="right_shoulder_pitch_link.STL"/>
    <mesh name="right_shoulder_roll_link" file="right_shoulder_roll_link.STL"/>
    <mesh name="right_shoulder_yaw_link" file="right_shoulder_yaw_link.STL"/>
    <mesh name="right_elbow_pitch_link" file="right_elbow_pitch_link.STL"/>
    <mesh name="right_elbow_roll_link" file="right_elbow_roll_link.STL"/>
    <mesh name="right_wrist_pitch_link" file="right_wrist_pitch_link.STL"/>
    <mesh name="right_wrist_yaw_link" file="right_wrist_yaw_link.STL"/>
  </asset>

  <worldbody>
    <body name="pelvis" pos="0 0 0.78">
      <camera name="depth_cam"
        pos="0.0576235 0.01753 0.42987"
        euler="0 -0.79 0"
        fovy="79.3"
        mode="fixed"/>
      <inertial pos="4.6721e-06 -2.3326e-07 -0.030542" mass="3.13" 
                diaginertia="0.010908 0.010341 0.006614"/>
      <joint name="floating_base_joint" type="free" limited="false" actuatorfrclimited="false"/>
      <geom type="mesh" contype="0" conaffinity="0" group="1" density="0" rgba="0.77 0.75 0.73 1" mesh="pelvis"/>
      
      <!-- Torso (fixed to pelvis) -->
      <geom pos="0 0 0.05725" type="mesh" contype="0" conaffinity="0" group="1" density="0" rgba="0.7 0.7 0.7 1" mesh="torso"/>
      <geom pos="0 0 0.20725" type="box" size="0.05 0.075 0.1" rgba="0.7 0.7 0.7 1"/>

      <!-- Left Leg -->
      <body name="left_leg_pitch_link" pos="0 0.057 -0.06025">
        <inertial pos="-0.0022424 0.052941 0.0018571" mass="1.06" 
                  diaginertia="0.0019452 0.0012366 0.0015468"/>
        <joint name="left_leg_pitch_joint" pos="0 0 0" axis="0 1 0" range="-2.792 2.792" actuatorfrcrange="-90 90"/>
        <geom type="mesh" contype="0" conaffinity="0" group="1" density="0" rgba="0.7 0.7 0.7 1" mesh="left_leg_pitch_link"/>
        
        <body name="left_leg_roll_link" pos="0 0.06 0">
          <inertial pos="0.002441 3.17e-05 -0.092183" mass="0.8" 
                    diaginertia="0.0015404 0.001629 0.00094122"/>
          <joint name="left_leg_roll_joint" pos="0 0 0" axis="1 0 0" range="-0.087 3.037" actuatorfrcrange="-90 90"/>
          <geom type="mesh" contype="0" conaffinity="0" group="1" density="0" rgba="0.7 0.7 0.7 1" mesh="left_leg_roll_link"/>
          <geom type="mesh" rgba="0.7 0.7 0.7 1" mesh="left_leg_roll_link"/>
          
          <body name="left_leg_yaw_link" pos="0 0 -0.127">
            <inertial pos="0.0010862 -0.00087371 -0.15709" mass="2.93" 
                      diaginertia="0.0082847 0.009843 0.0036644"/>
            <joint name="left_leg_yaw_joint" pos="0 0 0" axis="0 0 1" range="-2.269 2.269" actuatorfrcrange="-60 60"/>
            <geom type="mesh" contype="0" conaffinity="0" group="1" density="0" rgba="0.7 0.7 0.7 1" mesh="left_leg_yaw_link"/>
            <geom type="mesh" rgba="0.7 0.7 0.7 1" mesh="left_leg_yaw_link"/>
            
            <body name="left_knee_pitch_link" pos="0 0 -0.173">
              <inertial pos="-0.0032204 0.0014598 -0.13449" mass="2.19" 
                        diaginertia="0.016813 0.017944 0.0029858"/>
              <joint name="left_knee_pitch_joint" pos="0 0 0" axis="0 1 0" range="-0.052 2.618" actuatorfrcrange="-150 150"/>
              <geom type="mesh" contype="0" conaffinity="0" group="1" density="0" rgba="0.7 0.7 0.7 1" mesh="left_knee_pitch_link"/>
              <geom pos="0 0 -0.13" type="box" size="0.065 0.035 0.07" rgba="0.7 0.7 0.7 1"/>
              
              <body name="left_ankle_pitch_link" pos="0 0 -0.3">
                <inertial pos="0 0 0" mass="0.16" diaginertia="0.03 0.03 0.03"/>
                <joint name="left_ankle_pitch_joint" pos="0 0 0" axis="0 1 0" range="-2.094 2.094" actuatorfrcrange="-36 36"/>
                <geom type="mesh" contype="0" conaffinity="0" group="1" density="0" rgba="0.7 0.7 0.7 1" mesh="left_ankle_pitch_link"/>
                
                <body name="left_ankle_roll_link" pos="0 0 0">
                  <inertial pos="0.018367 0 -0.022988" mass="1.01" diaginertia="0.01 0.01 0.01"/>
                  <joint name="left_ankle_roll_joint" pos="0 0 0" axis="1 0 0" range="-0.349 0.349" actuatorfrcrange="-36 36"/>
                  <geom type="mesh" contype="0" conaffinity="0" group="1" density="0" rgba="0.7 0.7 0.7 1" mesh="left_ankle_roll_link"/>
                  <geom size="0.055 0.05 0.005" pos="0.0925 0 -0.038" type="box" rgba="0.2 0.2 0.2 1"/>
                  <geom size="0.065 0.04 0.005" pos="-0.0285 0 -0.038" type="box" rgba="0.2 0.2 0.2 1"/>
                </body>
              </body>
            </body>
          </body>
        </body>
      </body>

      <!-- Right Leg -->
      <body name="right_leg_pitch_link" pos="0 -0.057 -0.06025">
        <inertial pos="-0.0022424 -0.052767 0.0018571" mass="1.06" 
                  diaginertia="0.0019426 0.0012366 0.0015442"/>
        <joint name="right_leg_pitch_joint" pos="0 0 0" axis="0 1 0" range="-2.792 2.792" actuatorfrcrange="-90 90"/>
        <geom type="mesh" contype="0" conaffinity="0" group="1" density="0" rgba="0.7 0.7 0.7 1" mesh="right_leg_pitch_link"/>
        
        <body name="right_leg_roll_link" pos="0 -0.06 0">
          <inertial pos="0.002441 3.17e-05 -0.092183" mass="0.8" 
                    diaginertia="0.0015404 0.001629 0.00094122"/>
          <joint name="right_leg_roll_joint" pos="0 0 0" axis="1 0 0" range="-3.037 0.087" actuatorfrcrange="-90 90"/>
          <geom type="mesh" contype="0" conaffinity="0" group="1" density="0" rgba="0.7 0.7 0.7 1" mesh="right_leg_roll_link"/>
          <geom type="mesh" rgba="0.7 0.7 0.7 1" mesh="right_leg_roll_link"/>
          
          <body name="right_leg_yaw_link" pos="0 0 -0.127">
            <inertial pos="0.0010862 0.00087371 -0.15709" mass="2.93" 
                      diaginertia="0.0082847 0.009843 0.0036644"/>
            <joint name="right_leg_yaw_joint" pos="0 0 0" axis="0 0 1" range="-2.269 2.269" actuatorfrcrange="-60 60"/>
            <geom type="mesh" contype="0" conaffinity="0" group="1" density="0" rgba="0.7 0.7 0.7 1" mesh="right_leg_yaw_link"/>
            <geom type="mesh" rgba="0.7 0.7 0.7 1" mesh="right_leg_yaw_link"/>
            
            <body name="right_knee_pitch_link" pos="0 0 -0.173">
              <inertial pos="-0.0032204 -0.0014598 -0.13449" mass="2.19" 
                        diaginertia="0.016812 0.017943 0.0029855"/>
              <joint name="right_knee_pitch_joint" pos="0 0 0" axis="0 1 0" range="-0.052 2.618" actuatorfrcrange="-150 150"/>
              <geom type="mesh" contype="0" conaffinity="0" group="1" density="0" rgba="0.7 0.7 0.7 1" mesh="right_knee_pitch_link"/>
              <geom pos="0 0 -0.13" type="box" size="0.065 0.035 0.07" rgba="0.7 0.7 0.7 1"/>
              
              <body name="right_ankle_pitch_link" pos="0 0 -0.3">
                <inertial pos="0 0 0" mass="0.16" diaginertia="0.03 0.03 0.03"/>
                <joint name="right_ankle_pitch_joint" pos="0 0 0" axis="0 1 0" range="-2.094 2.094" actuatorfrcrange="-36 36"/>
                <geom type="mesh" contype="0" conaffinity="0" group="1" density="0" rgba="0.7 0.7 0.7 1" mesh="right_ankle_pitch_link"/>
                
                <body name="right_ankle_roll_link" pos="0 0 0">
                  <inertial pos="0.018366 0 -0.023002" mass="1.01" diaginertia="0.01 0.01 0.01"/>
                  <joint name="right_ankle_roll_joint" pos="0 0 0" axis="1 0 0" range="-0.349 0.349" actuatorfrcrange="-36 36"/>
                  <geom type="mesh" contype="0" conaffinity="0" group="1" density="0" rgba="0.7 0.7 0.7 1" mesh="right_ankle_roll_link"/>
                  <geom size="0.055 0.05 0.005" pos="0.0925 0 -0.038" type="box" rgba="0.2 0.2 0.2 1"/>
                  <geom size="0.065 0.04 0.005" pos="-0.0285 0 -0.038" type="box" rgba="0.2 0.2 0.2 1"/>
                </body>
              </body>
            </body>
          </body>
        </body>
      </body>

      <!-- Left Arm -->
      <body name="left_shoulder_pitch_link" pos="0 0.079102 0.37797" quat="0.991 0.131 0 0">
        <inertial pos="0.0074125 0.055258 2.03e-05" mass="0.51" 
                  diaginertia="0.00040726 0.00033867 0.00048429"/>
        <joint name="left_shoulder_pitch_joint" pos="0 0 0" axis="0 1 0" range="-1.57 1.57" actuatorfrcrange="-60 60"/>
        <geom type="mesh" contype="0" conaffinity="0" group="1" density="0" rgba="0.7 0.7 0.7 1" mesh="left_shoulder_pitch_link"/>
        <geom pos="0 0.064 0" quat="0.991 -0.131 0 0" type="mesh" contype="0" conaffinity="0" group="1" density="0" rgba="0.7 0.7 0.7 1" mesh="left_shoulder_roll_link"/>
        <geom pos="0.00013761 0.064 -0.103" quat="0.991 -0.131 0 0" type="mesh" contype="0" conaffinity="0" group="1" density="0" rgba="0.7 0.7 0.7 1" mesh="left_shoulder_yaw_link"/>
        
        <body name="left_elbow_pitch_link" pos="0 0.064 -0.2" quat="0.991 -0.131 0 0">
          <inertial pos="0.073356 0.0084377 7.54e-06" mass="0.64" 
                    diaginertia="0.00039885 0.00064086 0.00071392"/>
          <joint name="left_elbow_pitch_joint" pos="0 0 0" axis="0 1 0" range="-1.57 1.57" actuatorfrcrange="-36 36"/>
          <geom type="mesh" contype="0" conaffinity="0" group="1" density="0" rgba="0.7 0.7 0.7 1" mesh="left_elbow_pitch_link"/>
          <geom type="mesh" rgba="0.7 0.7 0.7 1" mesh="left_elbow_pitch_link"/>
          <geom pos="0.103 -0.00013761 0" type="mesh" contype="0" conaffinity="0" group="1" density="0" rgba="0.7 0.7 0.7 1" mesh="left_elbow_roll_link"/>
          <geom pos="0.2 0 0" type="mesh" contype="0" conaffinity="0" group="1" density="0" rgba="0.7 0.7 0.7 1" mesh="left_wrist_pitch_link"/>
          <geom pos="0.2 0 0" type="mesh" contype="0" conaffinity="0" group="1" density="0" rgba="1 1 1 1" mesh="left_wrist_yaw_link"/>
        </body>
      </body>

      <!-- Right Arm -->
      <body name="right_shoulder_pitch_link" pos="0 -0.079102 0.37797" quat="0.991 -0.131 0 0">
        <inertial pos="0.0074125 -0.055258 1.602e-05" mass="0.51" 
                  diaginertia="0.00040726 0.00033867 0.00048429"/>
        <joint name="right_shoulder_pitch_joint" pos="0 0 0" axis="0 1 0" range="-1.57 1.57" actuatorfrcrange="-60 60"/>
        <geom type="mesh" contype="0" conaffinity="0" group="1" density="0" rgba="0.7 0.7 0.7 1" mesh="right_shoulder_pitch_link"/>
        <geom pos="0 -0.064 0" quat="0.991 0.131 0 0" type="mesh" contype="0" conaffinity="0" group="1" density="0" rgba="0.7 0.7 0.7 1" mesh="right_shoulder_roll_link"/>
        <geom pos="0.00013761 -0.064 -0.103" quat="0.991 0.131 0 0" type="mesh" contype="0" conaffinity="0" group="1" density="0" rgba="0.7 0.7 0.7 1" mesh="right_shoulder_yaw_link"/>
        
        <body name="right_elbow_pitch_link" pos="0 -0.064 -0.2" quat="0.991 0.131 0 0">
          <inertial pos="0.073356 -0.0084377 7.54e-06" mass="0.64" 
                    diaginertia="0.00039885 0.00064086 0.00071392"/>
          <joint name="right_elbow_pitch_joint" pos="0 0 0" axis="0 1 0" range="-1.57 1.57" actuatorfrcrange="-36 36"/>
          <geom type="mesh" contype="0" conaffinity="0" group="1" density="0" rgba="0.7 0.7 0.7 1" mesh="right_elbow_pitch_link"/>
          <geom type="mesh" rgba="0.7 0.7 0.7 1" mesh="right_elbow_pitch_link"/>
          <geom pos="0.103 0.00013761 0" type="mesh" contype="0" conaffinity="0" group="1" density="0" rgba="0.7 0.7 0.7 1" mesh="right_elbow_roll_link"/>
          <geom pos="0.2 0 0" type="mesh" contype="0" conaffinity="0" group="1" density="0" rgba="0.7 0.7 0.7 1" mesh="right_wrist_pitch_link"/>
          <geom pos="0.2 0 0" type="mesh" contype="0" conaffinity="0" group="1" density="0" rgba="1 1 1 1" mesh="right_wrist_yaw_link"/>
        </body>
      </body>
    </body>
  </worldbody>

  <actuator>
    <motor name="left_leg_pitch_joint" joint="left_leg_pitch_joint"/>
    <motor name="left_leg_roll_joint" joint="left_leg_roll_joint"/>
    <motor name="left_leg_yaw_joint" joint="left_leg_yaw_joint"/>
    <motor name="left_knee_pitch_joint" joint="left_knee_pitch_joint"/>
    <motor name="left_ankle_pitch_joint" joint="left_ankle_pitch_joint"/>
    <motor name="left_ankle_roll_joint" joint="left_ankle_roll_joint"/>
    <motor name="right_leg_pitch_joint" joint="right_leg_pitch_joint"/>
    <motor name="right_leg_roll_joint" joint="right_leg_roll_joint"/>
    <motor name="right_leg_yaw_joint" joint="right_leg_yaw_joint"/>
    <motor name="right_knee_pitch_joint" joint="right_knee_pitch_joint"/>
    <motor name="right_ankle_pitch_joint" joint="right_ankle_pitch_joint"/>
    <motor name="right_ankle_roll_joint" joint="right_ankle_roll_joint"/>
    <motor name="left_shoulder_pitch_joint" joint="left_shoulder_pitch_joint"/>
    <motor name="left_elbow_pitch_joint" joint="left_elbow_pitch_joint"/>
    <motor name="right_shoulder_pitch_joint" joint="right_shoulder_pitch_joint"/>
    <motor name="right_elbow_pitch_joint" joint="right_elbow_pitch_joint"/>
  </actuator>

</mujoco>
